<?xml version="1.0"?>
<robot name="collector"
    xmlns:xacro="http://ros.org/wiki/xacro">


    <xacro:include filename="$(find robot_description)/src/description/robot_parts/collector/segment.xacro" />


    <xacro:macro name="collector">
        <!-- <xacro:segment name="segment_central" x="0.7" y="0.05" z="0.2" joint_parent="base_link" joint_origin_xyz="0.25 0.0 0" joint_origin_rpy="0 0 ${0.5 * pi}"/> -->

        <gazebo reference="segment_central">
            <visual>  
            <material>  
            <ambient>1. 0.3 0.3 1.0</ambient>  
            <diffuse>1. 0.3 0.3 1.0</diffuse>  
            <specular>1. 0.3 0.3 1.0</specular>  
            <emissive>1. 0.3 0.3 1.0</emissive>  
            </material>  
            </visual> 
        </gazebo>

        <link name="segment_central">
            <visual>
            <geometry>
                <!-- <box size="0.7 0.05 0.2"/> -->
                <box size="0.7 0.01 0.2"/>
            </geometry>
            <material name="Brown">
                <color rgba="0.30 0.15 0.0 1.0"/>
            </material>
            </visual>
            <!-- <collision>
            <origin xyz="0 0 0" rpy="0 0 0"/>
            <geometry>0 0.0 0.0 1.0
                <box size="0.7 0.05 0.2"/>
            </geometry>
            </collision> -->

            <xacro:box_inertia m="0.1" w="0.7" d="0.05" h="0.2"/>
        </link>

        <joint name="segment_central_joint" type="revolute">
            <axis xyz="1 0 0"/>
            <!-- <origin xyz="0.25 -0.23 0" rpy="-1.5 0 ${-0.5 * pi}"/> -->
            <origin xyz="-0.5 -0.23 0" rpy="${0 * pi} ${0 * pi} ${0 * pi}"/>
            <parent link="base_link"/>
            <child link="segment_central"/>
            <limit effort="1000.0" lower="-0.15" upper="0.15" velocity="30"/>
            <!-- <dynamics damping="0.0" friction="0.0"/> -->
        </joint>

        <ros2_control name="GazeboSystem" type="system">
            <hardware>
            <plugin>gazebo_ros2_control/GazeboSystem</plugin>
            </hardware>

            <joint name="segment_central_joint">
                <command_interface name="velocity">
                    <param name="min">-0.10</param>
                    <param name="max">0.10</param>
                </command_interface>
                <state_interface name="position"/>
                <state_interface name="velocity"/>
                <state_interface name="effort"/>
            </joint>
        </ros2_control>

        <gazebo>
            <plugin filename="libgazebo_ros2_control.so" name="gazebo_ros2_control">
            <parameters>$(find robot_description)/config/gripper_controller.yaml</parameters>
            
            </plugin>
        </gazebo>

        <!-- <xacro:segment name="segment_d1" x="0.3" y="0.05" z="0.2" joint_parent="segment_central" joint_origin_xyz="-.25 -.32 0" joint_origin_rpy="0 0 ${0.16 * pi}"/>

        <xacro:segment name="segment_d2" x="0.3" y="0.05" z="0.2" joint_parent="segment_d1" joint_origin_xyz="-0.30 -0.07 0" joint_origin_rpy="0 0 ${0.16 * pi}"/>

        <xacro:segment name="segment_d3" x="0.3" y="0.05" z="0.2" joint_parent="segment_d2" joint_origin_xyz="-0.15 -0.1 0" joint_origin_rpy="0 0 ${-0.32* pi}"/>

        <xacro:segment name="segment_g1" x="0.3" y="0.05" z="0.2" joint_parent="segment_central" joint_origin_xyz="0.25 -0.32 0" joint_origin_rpy="0 0 ${-0.16* pi}"/>

        <xacro:segment name="segment_g2" x="0.3" y="0.05" z="0.2" joint_parent="segment_g1" joint_origin_xyz="0.30 -0.07 0" joint_origin_rpy="0 0 ${-0.16* pi}"/>

        <xacro:segment name="segment_g3" x="0.3" y="0.05" z="0.2" joint_parent="segment_g2" joint_origin_xyz="0.15 -0.1 0" joint_origin_rpy="0 0 ${0.32* pi}"/>





        <xacro:segment name="segment_triangled" x="0.3" y="0.05" z="0.2"  joint_parent="segment_central" joint_origin_xyz="-0.25 -0.12 0" joint_origin_rpy="0 0 ${-0.25* pi}"/>

        <xacro:segment name="segment_triangleg" x="0.3" y="0.05" z="0.2"  joint_parent="segment_central" joint_origin_xyz="0.25 -0.12 0" joint_origin_rpy="0 0 ${0.25* pi}"/> -->


    </xacro:macro>

</robot>
